Workbook

Sheet Cover
A1: MATH 5380 — Project 1 (Long-Only Multi-Asset, Black-Litterman)
A3: Data file: | B3: E:\Columbia_Files\MATH5380\project\Data for final project 1.xlsx
A4: Output: | B4: E:\Columbia_Files\MATH5380\project\project\MATH5380-project\project1_results.xlsx
A6: Benchmark monthly return = same convention as code: constant year-end mkt weights within each calendar year (see report).
A7: Statistics below use Excel formulas referencing Data_Monthly.

Sheet Data_Monthly
A1: Date | B1: Portfolio_Monthly_Ret | C1: Benchmark_Monthly_Ret | D1: Active_Monthly | E1: Wealth_Index_Portfolio | F1: Wealth_Index_Benchmark
A2: 39478 | B2: -0.023674922 | C2: -0.033715163 | D2: =B2-C2 -> 0.010040241 | E2: =1*(1+B2) -> 0.97632508 | F2: =1*(1+C2) -> 0.96628484
A3: 39507 | B3: 0.0031097868 | C3: 0.0081346061 | D3: =B3-C3 -> -0.0050248193 | E3: =E2*(1+B3) -> 0.97936124 | F3: =F2*(1+C3) -> 0.97414518
A4: 39538 | B4: 0.0036975165 | C4: 0.00060108135 | D4: =B4-C4 -> 0.0030964352 | E4: =E3*(1+B4) -> 0.98298244 | F4: =F3*(1+C4) -> 0.97473072
A5: 39568 | B5: 0.016677048 | C5: 0.023052632 | D5: =B5-C5 -> -0.0063755835 | E5: =E4*(1+B5) -> 0.99937569 | F5: =F4*(1+C5) -> 0.99720083
A6: 39598 | B6: 0.0043575339 | C6: 0.0057198291 | D6: =B6-C6 -> -0.0013622952 | E6: =E5*(1+B6) -> 1.0037305 | F6: =F5*(1+C6) -> 1.0029047
A7: 39629 | B7: -0.037433684 | C7: -0.045774847 | D7: =B7-C7 -> 0.0083411636 | E7: =E6*(1+B7) -> 0.96615717 | F7: =F6*(1+C7) -> 0.95699684
A8: 39660 | B8: -0.0083951447 | C8: -0.013073397 | D8: =B8-C8 -> 0.0046782522 | E8: =E7*(1+B8) -> 0.95804614 | F8: =F7*(1+C8) -> 0.94448564
A9: 39689 | B9: -0.011399855 | C9: -0.017557504 | D9: =B9-C9 -> 0.0061576488 | E9: =E8*(1+B9) -> 0.94712456 | F9: =F8*(1+C9) -> 0.92790283
A10: 39721 | B10: -0.071737548 | C10: -0.083138635 | D10: =B10-C10 -> 0.011401086 | E10: =E9*(1+B10) -> 0.87918016 | F10: =F9*(1+C10) -> 0.85075826
A11: 39752 | B11: -0.11231316 | C11: -0.13267891 | D11: =B11-C11 -> 0.020365748 | E11: =E10*(1+B11) -> 0.78043666 | F11: =F10*(1+C11) -> 0.73788058
A12: 39780 | B12: -0.020374085 | C12: -0.027552805 | D12: =B12-C12 -> 0.0071787198 | E12: =E11*(1+B12) -> 0.76453598 | F12: =F11*(1+C12) -> 0.7175499
A13: 39813 | B13: 0.049005066 | C13: 0.051237125 | D13: =B13-C13 -> -0.0022320584 | E13: =E12*(1+B13) -> 0.80200212 | F13: =F12*(1+C13) -> 0.7543151
A14: 39843 | B14: -0.042243135 | C14: -0.050553233 | D14: =B14-C14 -> 0.0083100975 | E14: =E13*(1+B14) -> 0.76812303 | F14: =F13*(1+C14) -> 0.71618203
... A217: 46022 | B217: 0.0025989879 | C217: 0.0064999835 | D217: =B217-C217 -> -0.0039009956 | E217: =E216*(1+B217) -> 2.3105754 | F217: =F216*(1+C217) -> 2.1861215

Sheet Total_Return_Statistics
A1: Total Return Statistics
A4: Label | B4: Portfolio | C4: Benchmark
A5: Geometrically annualized total return (full sample) | B5: =Data_Monthly!E217^(12/COUNT(Data_Monthly!$B$2:$B$217))-1 -> 0.047626981 | C5: =Data_Monthly!F217^(12/COUNT(Data_Monthly!$C$2:$C$217))-1 -> 0.044409455
A6: Annualized volatility of total returns (monthly, ann.) | B6: =_xlfn.STDEV.S(Data_Monthly!$B$2:$B$217)*SQRT(12) -> 0.087822899 | C6: =_xlfn.STDEV.S(Data_Monthly!$C$2:$C$217)*SQRT(12) -> 0.10007915

Sheet Active_Return_Statistics
A1: Active Return Statistics
A4: Arithmetically annualized active return (vs benchmark) | B4: =AVERAGE(Data_Monthly!$D$2:$D$217)*12 -> 0.0019167726
A5: Annualized volatility of active returns (tracking error) | B5: =_xlfn.STDEV.S(Data_Monthly!$D$2:$D$217)*SQRT(12) -> 0.017062894
A6: Information ratio | B6: =B4/B5 -> 0.11233573

Sheet Gross_Returns
A1: Gross Returns
A2: Growth of $1 (end-of-month wealth; values reference Data_Monthly columns E–F)
A3: Date | B3: Portfolio wealth ($1 start) | C3: Benchmark wealth ($1 start)
A4: =Data_Monthly!A2 -> 39478 | B4: =Data_Monthly!E2 -> 0.97632508 | C4: =Data_Monthly!F2 -> 0.96628484
A5: =Data_Monthly!A3 -> 39507 | B5: =Data_Monthly!E3 -> 0.97936124 | C5: =Data_Monthly!F3 -> 0.97414518
A6: =Data_Monthly!A4 -> 39538 | B6: =Data_Monthly!E4 -> 0.98298244 | C6: =Data_Monthly!F4 -> 0.97473072
A7: =Data_Monthly!A5 -> 39568 | B7: =Data_Monthly!E5 -> 0.99937569 | C7: =Data_Monthly!F5 -> 0.99720083
A8: =Data_Monthly!A6 -> 39598 | B8: =Data_Monthly!E6 -> 1.0037305 | C8: =Data_Monthly!F6 -> 1.0029047
A9: =Data_Monthly!A7 -> 39629 | B9: =Data_Monthly!E7 -> 0.96615717 | C9: =Data_Monthly!F7 -> 0.95699684
A10: =Data_Monthly!A8 -> 39660 | B10: =Data_Monthly!E8 -> 0.95804614 | C10: =Data_Monthly!F8 -> 0.94448564
A11: =Data_Monthly!A9 -> 39689 | B11: =Data_Monthly!E9 -> 0.94712456 | C11: =Data_Monthly!F9 -> 0.92790283
A12: =Data_Monthly!A10 -> 39721 | B12: =Data_Monthly!E10 -> 0.87918016 | C12: =Data_Monthly!F10 -> 0.85075826
A13: =Data_Monthly!A11 -> 39752 | B13: =Data_Monthly!E11 -> 0.78043666 | C13: =Data_Monthly!F11 -> 0.73788058
A14: =Data_Monthly!A12 -> 39780 | B14: =Data_Monthly!E12 -> 0.76453598 | C14: =Data_Monthly!F12 -> 0.7175499
A15: =Data_Monthly!A13 -> 39813 | B15: =Data_Monthly!E13 -> 0.80200212 | C15: =Data_Monthly!F13 -> 0.7543151
... A219: =Data_Monthly!A217 -> 46022 | B219: =Data_Monthly!E217 -> 2.3105754 | C219: =Data_Monthly!F217 -> 2.1861215

Sheet Weights_Annual
A1: Weights (market & optimal) — each row = hold year of portfolio
A2: Year | B2: Russell 1000 Value | C2: Russell 1000 Growth | D2: Russell 2000 Value | E2: Russell 2000 Growth | F2: MSCI World Ex USA Value NR USD | G2: MSCI World Ex USA Growth NR USD | H2: MSCI World Ex USA Small Value NR USD | I2: MSCI World Ex USA Small Growth NR USD | J2: MSCI EM Value NR USD | K2: MSCI EM Growth NR USD | L2: MSCI EM Small Value NR USD | M2: MSCI EM Small Growth NR USD | N2: Bloomberg Barclays US Aggregate | O2: Bloomberg Barclays Global Aggregate x USD | P2: Bloomberg Barclays Global Inflation-Linked USD | Q2: Bloomberg Barclays US Municipal Bond | R2: Bloomberg Barclays Global High Yield USD
A3: — Market cap (or benchmark) weights
A4: 2008 | B4: 0.10589393 | C4: 0.1167898 | D4: 0.0089659428 | E4: 0.01036784 | F4: 0.11281475 | G4: 0.11477024 | H4: 0.012333387 | I4: 0.013048515 | J4: 0.027058691 | K4: 0.025615952 | L4: 0.0036886974 | M4: 0.0036429253 | N4: 0.15260138 | O4: 0.24252884 | P4: 0.018546167 | Q4: 0.016291699 | R4: 0.01504124
A5: 2009 | B5: 0.085049806 | C5: 0.084437075 | D5: 0.0075043942 | E5: 0.0067619963 | F5: 0.077835687 | G5: 0.082676746 | H5: 0.0067581405 | I5: 0.0076712065 | J5: 0.016617664 | K5: 0.01517927 | L5: 0.0021172258 | M5: 0.0020864752 | N5: 0.21822708 | O5: 0.33160502 | P5: 0.023330857 | Q5: 0.020465428 | R5: 0.011675929
A6: 2010 | B6: 0.082033553 | C6: 0.084239255 | D6: 0.0072502359 | E6: 0.0068595054 | F6: 0.084125744 | G6: 0.085388863 | H6: 0.010241739 | I6: 0.010247489 | J6: 0.023743683 | K6: 0.024559455 | L6: 0.0031850631 | M6: 0.0032795872 | N6: 0.20443317 | O6: 0.31351798 | P6: 0.021262649 | Q6: 0.018377637 | R6: 0.017254388
A7: 2011 | B7: 0.086912289 | C7: 0.088477695 | D7: 0.0077596478 | E7: 0.0081362856 | F7: 0.080997741 | G7: 0.084398285 | H7: 0.011322232 | I7: 0.012000867 | J7: 0.025592709 | K7: 0.025707684 | L7: 0.0035787454 | M7: 0.0035413534 | N7: 0.20362666 | O7: 0.3022915 | P7: 0.020546185 | Q7: 0.016322203 | R7: 0.01878792
A8: 2012 | B8: 0.087575833 | C8: 0.087230376 | D8: 0.0074659556 | E8: 0.0074992697 | F8: 0.071996565 | G8: 0.072228538 | H8: 0.0099621808 | I8: 0.010004009 | J8: 0.021122758 | K8: 0.021972259 | L8: 0.0027785497 | M8: 0.0027860027 | N8: 0.21571233 | O8: 0.32038881 | P8: 0.024547265 | Q8: 0.0173902 | R8: 0.019339091
A9: 2013 | B9: 0.091846533 | C9: 0.086884757 | D9: 0.0076233645 | E9: 0.0071395296 | F9: 0.074541441 | G9: 0.074922869 | H9: 0.010283559 | I9: 0.010036948 | J9: 0.02274296 | K9: 0.024107564 | L9: 0.0030853603 | M9: 0.0030619944 | N9: 0.20859274 | O9: 0.31119758 | P9: 0.025342372 | Q9: 0.016502834 | R9: 0.022087595
A10: 2014 | B10: 0.10511786 | C10: 0.10954149 | D10: 0.0091543277 | E10: 0.0096980435 | F10: 0.08140076 | G10: 0.082038933 | H10: 0.011425147 | I10: 0.011622873 | J10: 0.019701926 | K10: 0.021312683 | L10: 0.0029839109 | M10: 0.0029382935 | N10: 0.1886648 | O10: 0.28271894 | P10: 0.024081661 | Q10: 0.014313051 | R10: 0.023285307
A11: 2015 | B11: 0.11430186 | C11: 0.11746828 | D11: 0.0096633919 | E11: 0.0097747842 | F11: 0.074219882 | G11: 0.076392314 | H11: 0.011050956 | I11: 0.010972126 | J11: 0.018876329 | K11: 0.021247783 | L11: 0.0031740773 | M11: 0.003142266 | N11: 0.19393909 | O11: 0.27126003 | P11: 0.026300826 | Q11: 0.014773785 | R11: 0.023442217
A12: 2016 | B12: 0.11072821 | C12: 0.11853246 | D12: 0.0093567227 | E12: 0.0095614668 | F12: 0.073507625 | G12: 0.075467044 | H12: 0.01141047 | I12: 0.011934767 | J12: 0.018753284 | K12: 0.019262769 | L12: 0.0031925095 | M12: 0.0032676298 | N12: 0.20362953 | O12: 0.26534104 | P12: 0.026544852 | Q12: 0.015398286 | R12: 0.024111337
A13: 2017 | B13: 0.11825169 | C13: 0.1129756 | D13: 0.010529379 | E13: 0.0094723867 | F13: 0.074331621 | G13: 0.068818688 | H13: 0.011858965 | I13: 0.011355591 | J13: 0.020706011 | K13: 0.020297257 | L13: 0.0031812337 | M13: 0.0031819147 | N13: 0.20489479 | O13: 0.26229842 | P13: 0.027380926 | Q13: 0.014873062 | R13: 0.025592463
A14: 2018 | B14: 0.11635533 | C14: 0.11843554 | D14: 0.0093041982 | E14: 0.01000769 | F14: 0.07597589 | G14: 0.076955795 | H14: 0.01324548 | I14: 0.013295828 | J14: 0.025005097 | K14: 0.025279573 | L14: 0.0037539856 | M14: 0.0038243119 | N14: 0.18742835 | O14: 0.25691365 | P14: 0.026597159 | Q14: 0.01351081 | R14: 0.024111319
A15: 2019 | B15: 0.11606712 | C15: 0.11378178 | D15: 0.0085602282 | E15: 0.0089551554 | F15: 0.067510098 | G15: 0.067183147 | H15: 0.011341797 | I15: 0.011120459 | J15: 0.023881781 | K15: 0.023467354 | L15: 0.0030374696 | M15: 0.0029643646 | N15: 0.20535612 | O15: 0.27171285 | P15: 0.027920809 | Q15: 0.014677132 | R15: 0.022462339
... A21: 2025 | B21: 0.15513384 | C21: 0.1858782 | D21: 0.008177174 | E21: 0.0086184757 | F21: 0.057793035 | G21: 0.057155121 | H21: 0.009201383 | I21: 0.0092575656 | J21: 0.023231956 | K21: 0.025301087 | L21: 0.0040999662 | M21: 0.0041712952 | N21: 0.17849439 | O21: 0.22824285 | P21: 0.017804765 | Q21: 0.010894957 | R21: 0.016543935
A23: — Optimal portfolio weights
A24: 2008 | B24: 0.087813925 | C24: 0.1667898 | D24: 0.00092354648 | E24: 0.021207234 | F24: 0.062814747 | G24: 0.064770237 | H24: 0 | I24: 1.2355569e-18 | J24: 0.0058839646 | K24: 0.0075895959 | L24: 0.014569984 | M24: 0.024460658 | N24: 0.20260138 | O24: 0.24536634 | P24: 0.038630929 | Q24: 0.056577656 | R24: 1.4094628e-18
A25: 2009 | B25: 0.10301964 | C25: 0.13443708 | D25: 0.0022823094 | E25: 0.012507185 | F25: 0.036006655 | G25: 0.032676746 | H25: 0 | I25: 4.6476788e-19 | J25: 1.8967278e-18 | K25: 0.0025906868 | L25: 0.0013236988 | M25: 2.9853057e-05 | N25: 0.26822708 | O25: 0.33643365 | P25: 5.430396e-18 | Q25: 0.070465428 | R25: 8.7565389e-18
A26: 2010 | B26: 0.12036307 | C26: 0.13423926 | D26: 0.017644773 | E26: 0.0075897625 | F26: 0.03496014 | G26: 0.035388863 | H26: 1.1509848e-18 | I26: 7.9102659e-19 | J26: 0.0059573047 | K26: 0.014902158 | L26: 0 | M26: 0 | N26: 0.25443317 | O26: 0.31648634 | P26: 0 | Q26: 0.05803516 | R26: 6.5674041e-18
A27: 2011 | B27: 0.12230034 | C27: 0.13847769 | D27: 0.025948335 | E27: 0.017762717 | F27: 0.030997741 | G27: 0.034398285 | H27: 5.1080247e-19 | I27: 4.7733523e-19 | J27: 0.00068634823 | K27: 0.010653026 | L27: 0 | M27: 1.4058116e-19 | N27: 0.25359644 | O27: 0.31426657 | P27: 0 | Q27: 0.050912499 | R27: 1.2124438e-18
A28: 2012 | B28: 0.10457993 | C28: 0.11470281 | D28: 0.039804843 | E28: 0.03042778 | F28: 0.021996565 | G28: 0.022228538 | H28: 0 | I28: 1.0435875e-19 | J28: 5.1456817e-19 | K28: 1.4157262e-18 | L28: 1.7497397e-19 | M28: 0 | N28: 0.26030152 | O28: 0.32371007 | P28: 0.032850711 | Q28: 0.049397226 | R28: 0
A29: 2013 | B29: 0.097795746 | C29: 0.12169843 | D29: 0.030588216 | E29: 0.035838912 | F29: 0.024541441 | G29: 0.024922869 | H29: 3.0615684e-19 | I29: 0 | J29: 1.8715477e-19 | K29: 0 | L29: 0 | M29: 6.2915254e-19 | N29: 0.25859274 | O29: 0.31086501 | P29: 0.028653803 | Q29: 0.066502834 | R29: 0
A30: 2014 | B30: 0.12158918 | C30: 0.14530881 | D30: 0.016805971 | E30: 0.022415613 | F30: 0.03140076 | G30: 0.032038933 | H30: 0 | I30: 0 | J30: 1.5732588e-19 | K30: 0 | L30: 5.9100675e-19 | M30: 0 | N30: 0.2386648 | O30: 0.29253088 | P30: 0.031102216 | Q30: 0.064313051 | R30: 0.003829795
A31: 2015 | B31: 0.12246757 | C31: 0.15172429 | D31: 0.017239932 | E31: 0.036235174 | F31: 0.024219882 | G31: 0.026392314 | H31: 0 | I31: 7.6394514e-19 | J31: 1.8881328e-18 | K31: 0 | L31: 1.6581038e-18 | M31: 2.0649877e-18 | N31: 0.24393909 | O31: 0.27701325 | P31: 0.035994712 | Q31: 0.064773785 | R31: 0
A32: 2016 | B32: 0.12408327 | C32: 0.14789507 | D32: 0.026190565 | E32: 0.042523336 | F32: 0.023507625 | G32: 0.025467044 | H32: 9.7225631e-19 | I32: 7.5541588e-19 | J32: 1.1890967e-18 | K32: 1.0489457e-19 | L32: 4.6722701e-20 | M32: 5.3857544e-19 | N32: 0.25362953 | O32: 0.25923179 | P32: 0.028507011 | Q32: 0.065398286 | R32: 0.00356647
A33: 2017 | B33: 0.1331029 | C33: 0.1629756 | D33: 0.020434215 | E33: 0.032776069 | F33: 0.024331621 | G33: 0.018818688 | H33: 0 | I33: 0 | J33: 0 | K33: 0.0076185241 | L33: 0.00015189428 | M33: 0 | N33: 0.25489479 | O33: 0.24374846 | P33: 0.036274169 | Q33: 0.064873062 | R33: 0
A34: 2018 | B34: 0.13190774 | C34: 0.16843554 | D34: 0.024605241 | E34: 0.023441837 | F34: 0.02597589 | G34: 0.026955795 | H34: 5.6026106e-19 | I34: 1.020959e-18 | J34: 3.4475758e-18 | K34: 0.0081752888 | L34: 0.0040896434 | M34: 0.001856045 | N34: 0.23742835 | O34: 0.25074391 | P34: 0.037503289 | Q34: 0.058881437 | R34: 0
A35: 2019 | B35: 0.11763191 | C35: 0.16378178 | D35: 0.0093908611 | E35: 0.03184373 | F35: 0.017510098 | G35: 0.032986119 | H35: 0 | I35: 1.1166158e-20 | J35: 0.0049289939 | K35: 0.00063396375 | L35: 0.0020154334 | M35: 0.011777884 | N35: 0.245321 | O35: 0.2775854 | P35: 0.034013221 | Q35: 0.050579606 | R35: 0
... A41: 2025 | B41: 0.13061537 | C41: 0.20050021 | D41: 0.0091895343 | E41: 0.018787773 | F41: 0.010004842 | G41: 0.034641266 | H41: 9.3733494e-05 | I41: 0.0035148439 | J41: 0.013866568 | K41: 0.011631326 | L41: 3.4794209e-19 | M41: 0 | N41: 0.22849439 | O41: 0.25006688 | P41: 0.039302654 | Q41: 0.0492906 | R41: 1.3010426e-18
A44: View portfolio weights (P rows) & Q (annual, relative return)
A45: View_ID | B45: Russell 1000 Value | C45: Russell 1000 Growth | D45: Russell 2000 Value | E45: Russell 2000 Growth | F45: MSCI World Ex USA Value NR USD | G45: MSCI World Ex USA Growth NR USD | H45: MSCI World Ex USA Small Value NR USD | I45: MSCI World Ex USA Small Growth NR USD | J45: MSCI EM Value NR USD | K45: MSCI EM Growth NR USD | L45: MSCI EM Small Value NR USD | M45: MSCI EM Small Growth NR USD | N45: Bloomberg Barclays US Aggregate | O45: Bloomberg Barclays Global Aggregate x USD | P45: Bloomberg Barclays Global Inflation-Linked USD | Q45: Bloomberg Barclays US Municipal Bond | R45: Bloomberg Barclays Global High Yield USD | S45: Q_annual
A46: View 1 | B46: 0 | C46: 1 | D46: 0 | E46: 0 | F46: 0 | G46: -1 | H46: 0 | I46: 0 | J46: 0 | K46: 0 | L46: 0 | M46: 0 | N46: 0 | O46: 0 | P46: 0 | Q46: 0 | R46: 0 | S46: 0.0075
A47: View 2 | B47: 0 | C47: 0 | D47: 0 | E47: 0 | F47: 0 | G47: 0 | H47: 0 | I47: 0 | J47: 0 | K47: 0 | L47: 0 | M47: 0 | N47: 1 | O47: 0 | P47: 0 | Q47: 0 | R47: -1 | S47: 0.004

Sheet Parameters
A1: Parameters (risk aversion & confidence in BL; same each year in this build)
A3: hold_year (portfolio applied year) | B3: delta (risk aversion, same in pi & MVO) | C3: tau (on Sigma for BL prior scale) | D3: omega_scale (views uncertainty multiplier; >1 = weaker views)
A4: 2008 | B4: 2.5 | C4: 0.05 | D4: 4
A5: 2009 | B5: 2.5 | C5: 0.05 | D5: 4
A6: 2010 | B6: 2.5 | C6: 0.05 | D6: 4
A7: 2011 | B7: 2.5 | C7: 0.05 | D7: 4
A8: 2012 | B8: 2.5 | C8: 0.05 | D8: 4
A9: 2013 | B9: 2.5 | C9: 0.05 | D9: 4
A10: 2014 | B10: 2.5 | C10: 0.05 | D10: 4
A11: 2015 | B11: 2.5 | C11: 0.05 | D11: 4
A12: 2016 | B12: 2.5 | C12: 0.05 | D12: 4
A13: 2017 | B13: 2.5 | C13: 0.05 | D13: 4
A14: 2018 | B14: 2.5 | C14: 0.05 | D14: 4
A15: 2019 | B15: 2.5 | C15: 0.05 | D15: 4
... A21: 2025 | B21: 2.5 | C21: 0.05 | D21: 4

Sheet Expected_Returns
A1: Expected Returns — market-implied π and Black–Litterman μ_BL (annual)
A3: — Market-implied (equilibrium) returns π = δ Σ w_mkt
A4: Year | B4: Russell 1000 Value | C4: Russell 1000 Growth | D4: Russell 2000 Value | E4: Russell 2000 Growth | F4: MSCI World Ex USA Value NR USD | G4: MSCI World Ex USA Growth NR USD | H4: MSCI World Ex USA Small Value NR USD | I4: MSCI World Ex USA Small Growth NR USD | J4: MSCI EM Value NR USD | K4: MSCI EM Growth NR USD | L4: MSCI EM Small Value NR USD | M4: MSCI EM Small Growth NR USD | N4: Bloomberg Barclays US Aggregate | O4: Bloomberg Barclays Global Aggregate x USD | P4: Bloomberg Barclays Global Inflation-Linked USD | Q4: Bloomberg Barclays US Municipal Bond | R4: Bloomberg Barclays Global High Yield USD
A5: 2008 | B5: 0.0087633995 | C5: 0.0084311577 | D5: 0.010945464 | E5: 0.014286537 | F5: 0.012906126 | G5: 0.013056538 | H5: 0.01283992 | I5: 0.015313062 | J5: 0.022200679 | K5: 0.022226196 | L5: 0.020280426 | M5: 0.020404481 | N5: 0.00025133014 | O5: 0.00373036 | P5: 0.0025860408 | Q5: 0.00059555408 | R5: 0.0050026264
A6: 2009 | B6: 0.029763936 | C6: 0.032969866 | D6: 0.032506941 | E6: 0.040012535 | F6: 0.042676421 | G6: 0.04425472 | H6: 0.047578868 | I6: 0.052345081 | J6: 0.059449655 | K6: 0.06254663 | L6: 0.064800549 | M6: 0.068444853 | N6: 0.0050187535 | O6: 0.0129004 | P6: 0.020078918 | Q6: 0.0052981276 | R6: 0.030727987
A7: 2010 | B7: 0.060450565 | C7: 0.056743288 | D7: 0.064753971 | E7: 0.066218042 | F7: 0.077740206 | G7: 0.071407772 | H7: 0.081859514 | I7: 0.080323723 | J7: 0.095291775 | K7: 0.094875254 | L7: 0.10550896 | M7: 0.10743874 | N7: 0.0075913952 | O7: 0.023054044 | P7: 0.029876483 | Q7: 0.0067450719 | R7: 0.046439021
A8: 2011 | B8: 0.075555861 | C8: 0.071513972 | D8: 0.083063489 | E8: 0.082953383 | F8: 0.096692159 | G8: 0.087796667 | H8: 0.10132665 | I8: 0.098941131 | J8: 0.10887807 | K8: 0.10891578 | L8: 0.12108398 | M8: 0.12161865 | N8: 0.0067384408 | O8: 0.029404374 | P8: 0.035146869 | Q8: 0.0060121345 | R8: 0.054080253
A9: 2012 | B9: 0.054519967 | C9: 0.04580248 | D9: 0.061876866 | E9: 0.05622858 | F9: 0.066408505 | G9: 0.058188313 | H9: 0.065238575 | I9: 0.059204433 | J9: 0.06773843 | K9: 0.066283415 | L9: 0.072995267 | M9: 0.069704466 | N9: 0.001659236 | O9: 0.023385828 | P9: 0.019470287 | Q9: -0.00025029916 | R9: 0.027052108
A10: 2013 | B10: 0.032244097 | C10: 0.032615259 | D10: 0.038112109 | E10: 0.040303841 | F10: 0.043635732 | G10: 0.042096069 | H10: 0.044523917 | I10: 0.043797845 | J10: 0.045596368 | K10: 0.046612069 | L10: 0.046727135 | M10: 0.044488992 | N10: -0.0011798625 | O10: 0.014308848 | P10: 0.011626249 | Q10: -0.00090211032 | R10: 0.019318107
A11: 2014 | B11: 0.022184569 | C11: 0.022474703 | D11: 0.027187919 | E11: 0.029465075 | F11: 0.031911128 | G11: 0.030937544 | H11: 0.032740643 | I11: 0.030951255 | J11: 0.035250588 | K11: 0.035140276 | L11: 0.035412375 | M11: 0.034879967 | N11: 0.00046340613 | O11: 0.0094291804 | P11: 0.0094046992 | Q11: 0.0010182434 | R11: 0.015123088
A12: 2015 | B12: 0.011905754 | C12: 0.013143991 | D12: 0.01507279 | E12: 0.015381494 | F12: 0.020526023 | G12: 0.018075722 | H12: 0.020949858 | I12: 0.019176579 | J12: 0.021528998 | K12: 0.019899064 | L12: 0.019580454 | M12: 0.018357059 | N12: 0.0013036771 | O12: 0.0068055084 | P12: 0.0069973891 | Q12: 0.002028724 | R12: 0.0086066124
A13: 2016 | B13: 0.013552238 | C13: 0.014420232 | D13: 0.013931206 | E13: 0.014205201 | F13: 0.019510801 | G13: 0.016848545 | H13: 0.017199511 | I13: 0.0155865 | J13: 0.018868526 | K13: 0.016907017 | L13: 0.015846344 | M13: 0.015379293 | N13: 0.0012772189 | O13: 0.0054733238 | P13: 0.006792476 | Q13: 0.0013451548 | R13: 0.0080427496
A14: 2017 | B14: 0.013936649 | C14: 0.014908189 | D14: 0.014399236 | E14: 0.016564819 | F14: 0.018214126 | G14: 0.017619854 | H14: 0.017489623 | I14: 0.017113219 | J14: 0.02321174 | K14: 0.020719887 | L14: 0.019660303 | M14: 0.017331945 | N14: 0.0011494473 | O14: 0.0072612414 | P14: 0.006209362 | Q14: 0.00066027543 | R14: 0.008934518
A15: 2018 | B15: 0.011880099 | C15: 0.013829635 | D15: 0.0095021351 | E15: 0.013385812 | F15: 0.016566209 | G15: 0.016405224 | H15: 0.016052216 | I15: 0.01583326 | J15: 0.021885047 | K15: 0.019770216 | L15: 0.019351299 | M15: 0.01698837 | N15: 0.00084083163 | O15: 0.0066141994 | P15: 0.0052804737 | Q15: 0.00070624512 | R15: 0.0077448948
A16: 2019 | B16: 0.011860301 | C16: 0.014907903 | D16: 0.012216933 | E16: 0.016738291 | F16: 0.013796115 | G16: 0.0156814 | H16: 0.016090983 | I16: 0.01807688 | J16: 0.019286669 | K16: 0.020351974 | L16: 0.018953815 | M16: 0.01840891 | N16: 0.001155362 | O16: 0.0068055072 | P16: 0.0046639643 | Q16: 0.0012451878 | R16: 0.0061014822
... A22: 2025 | B22: 0.048976963 | C22: 0.05829601 | D22: 0.06135379 | E22: 0.064662441 | F22: 0.044516718 | G22: 0.058747957 | H22: 0.05036533 | I22: 0.061298668 | J22: 0.040650583 | K22: 0.047752353 | L22: 0.037532935 | M22: 0.043811171 | N22: 0.022244953 | O22: 0.031521122 | P22: 0.035087286 | Q22: 0.02129664 | R22: 0.028986221
A25: — Black–Litterman blended E[r] μ_BL (annual)
A26: Year | B26: Russell 1000 Value | C26: Russell 1000 Growth | D26: Russell 2000 Value | E26: Russell 2000 Growth | F26: MSCI World Ex USA Value NR USD | G26: MSCI World Ex USA Growth NR USD | H26: MSCI World Ex USA Small Value NR USD | I26: MSCI World Ex USA Small Growth NR USD | J26: MSCI EM Value NR USD | K26: MSCI EM Growth NR USD | L26: MSCI EM Small Value NR USD | M26: MSCI EM Small Growth NR USD | N26: Bloomberg Barclays US Aggregate | O26: Bloomberg Barclays Global Aggregate x USD | P26: Bloomberg Barclays Global Inflation-Linked USD | Q26: Bloomberg Barclays US Municipal Bond | R26: Bloomberg Barclays Global High Yield USD
A27: 2008 | B27: 0.0063294857 | C27: 0.0074170851 | D27: 0.0079347824 | E27: 0.011247781 | F27: 0.0089504013 | G27: 0.0091915454 | H27: 0.008752016 | I27: 0.010572534 | J27: 0.016542183 | K27: 0.016941276 | L27: 0.015439722 | M27: 0.01572433 | N27: 0.00065405636 | O27: 0.0030863492 | P27: 0.0023762916 | Q27: 0.00067599787 | R27: 0.0034542887
A28: 2009 | B28: 0.022596487 | C28: 0.025409257 | D28: 0.02460483 | E28: 0.030022634 | F28: 0.0313844 | G28: 0.031961079 | H28: 0.034923977 | I28: 0.037808137 | J28: 0.043119363 | K28: 0.045241818 | L28: 0.047800123 | M28: 0.050259221 | N28: 0.0043315616 | O28: 0.0098599498 | P28: 0.015120356 | Q28: 0.0046532561 | R28: 0.022771538
A29: 2010 | B29: 0.051216146 | C29: 0.047102972 | D29: 0.055106907 | E29: 0.054579485 | F29: 0.062780302 | G29: 0.056406448 | H29: 0.064803158 | I29: 0.062445563 | J29: 0.075298176 | K29: 0.074509739 | L29: 0.082721702 | M29: 0.083853824 | N29: 0.0066080686 | O29: 0.019093197 | P29: 0.023990141 | Q29: 0.0054590493 | R29: 0.035454354
A30: 2011 | B30: 0.064029461 | C30: 0.059642327 | D30: 0.071283084 | E30: 0.069261966 | F30: 0.078161144 | G30: 0.069769738 | H30: 0.080517229 | I30: 0.077735634 | J30: 0.086156423 | K30: 0.085814267 | L30: 0.094920485 | M30: 0.094953129 | N30: 0.0057347427 | O30: 0.024088312 | P30: 0.027751432 | Q30: 0.0047034037 | R30: 0.041031101
A31: 2012 | B31: 0.04626655 | C31: 0.038779947 | D31: 0.052991524 | E31: 0.047290727 | F31: 0.052967168 | G31: 0.045836542 | H31: 0.05065845 | I31: 0.045791568 | J31: 0.053016258 | K31: 0.051865516 | L31: 0.055483148 | M31: 0.052869941 | N31: 0.0016675075 | O31: 0.019097132 | P31: 0.01569026 | Q31: -0.00053164265 | R31: 0.019425732
A32: 2013 | B32: 0.024087306 | C32: 0.025258746 | D32: 0.029062954 | E32: 0.030841096 | F32: 0.030580987 | G32: 0.029778602 | H32: 0.031119712 | I32: 0.031211979 | J32: 0.032171179 | K32: 0.032922484 | L32: 0.032333978 | M32: 0.030819626 | N32: -0.00084902038 | O32: 0.010366092 | P32: 0.0081072232 | Q32: -0.0003963287 | R32: 0.013220337
A33: 2014 | B33: 0.015824335 | C33: 0.016560138 | D33: 0.019419414 | E33: 0.021136551 | F33: 0.02081246 | G33: 0.020611095 | H33: 0.021550225 | I33: 0.020888845 | J33: 0.023404873 | K33: 0.023237067 | L33: 0.023101916 | M33: 0.023094628 | N33: 0.00052999463 | O33: 0.0065593755 | P33: 0.0065163328 | Q33: 0.0010402305 | R33: 0.0099765725
A34: 2015 | B34: 0.0089188657 | C34: 0.010577894 | D34: 0.011906574 | E34: 0.012522008 | F34: 0.012896879 | G34: 0.011960233 | H34: 0.013564852 | I34: 0.013094958 | J34: 0.014239425 | K34: 0.013398431 | L34: 0.012830114 | M34: 0.012430939 | N34: 0.0013372884 | O34: 0.0048246272 | P34: 0.00507324 | Q34: 0.0018745691 | R34: 0.0055149678
A35: 2016 | B35: 0.011160899 | C35: 0.012111777 | D35: 0.012219591 | E35: 0.01276648 | F35: 0.013568039 | G35: 0.012214104 | H35: 0.011783543 | I35: 0.011006773 | J35: 0.012912155 | K35: 0.012202682 | L35: 0.010876882 | M35: 0.010822421 | N35: 0.0013742399 | O35: 0.0037223624 | P35: 0.005018792 | Q35: 0.0013564846 | R35: 0.0056382075
A36: 2017 | B36: 0.011638041 | C36: 0.012971217 | D36: 0.012755451 | E36: 0.01498831 | F36: 0.012585936 | G36: 0.013180066 | H36: 0.012167097 | I36: 0.01239218 | J36: 0.016792813 | K36: 0.015548005 | L36: 0.014173079 | M36: 0.012516965 | N36: 0.0012412116 | O36: 0.0053662468 | P36: 0.0047933304 | Q36: 0.00069920757 | R36: 0.0061930381
A37: 2018 | B37: 0.0097469874 | C37: 0.011759251 | D37: 0.0080239724 | E37: 0.011224621 | F37: 0.011184575 | G37: 0.012028983 | H37: 0.011015277 | I37: 0.011229657 | J37: 0.015897501 | K37: 0.01460484 | L37: 0.014252684 | M37: 0.012435076 | N37: 0.00081485503 | O37: 0.0049682887 | P37: 0.0039785509 | Q37: 0.00051486955 | R37: 0.0052489669
A38: 2019 | B38: 0.010355072 | C38: 0.014044904 | D38: 0.011085751 | E38: 0.015642628 | F38: 0.0095955359 | G38: 0.012841392 | H38: 0.012222767 | I38: 0.014895988 | J38: 0.01530695 | K38: 0.016933526 | L38: 0.015543409 | M38: 0.015702438 | N38: 0.0012551077 | O38: 0.0058028744 | P38: 0.0038352195 | Q38: 0.0012268885 | R38: 0.0042520762
... A44: 2025 | B44: 0.045624917 | C44: 0.056329894 | D44: 0.057491901 | E44: 0.061896189 | F44: 0.040533689 | G44: 0.055488488 | H44: 0.046308782 | I44: 0.057385506 | J44: 0.037967297 | K44: 0.044870717 | L44: 0.034159351 | M44: 0.040222049 | N44: 0.022079129 | O44: 0.030328294 | P44: 0.033773989 | Q44: 0.020838447 | R44: 0.026727229

Sheet Sec08_FinalYr
A1: Section 8 — Final portfolio year: 2025 (annualized)
A3: Covariances (annualized) — use same Σ as in optimization for the final year
B4: Russell 1000 Value | C4: Russell 1000 Growth | D4: Russell 2000 Value | E4: Russell 2000 Growth | F4: MSCI World Ex USA Value NR USD | G4: MSCI World Ex USA Growth NR USD | H4: MSCI World Ex USA Small Value NR USD | I4: MSCI World Ex USA Small Growth NR USD | J4: MSCI EM Value NR USD | K4: MSCI EM Growth NR USD | L4: MSCI EM Small Value NR USD | M4: MSCI EM Small Growth NR USD | N4: Bloomberg Barclays US Aggregate | O4: Bloomberg Barclays Global Aggregate x USD | P4: Bloomberg Barclays Global Inflation-Linked USD | Q4: Bloomberg Barclays US Municipal Bond | R4: Bloomberg Barclays Global High Yield USD
A5: Russell 1000 Value | B5: 0.028532659 | C5: 0.026336277 | D5: 0.036700933 | E5: 0.035440295 | F5: 0.023465053 | G5: 0.02711852 | H5: 0.025540082 | I5: 0.029016456 | J5: 0.016858308 | K5: 0.018704108 | L5: 0.016871747 | M5: 0.018586928 | N5: 0.009064257 | O5: 0.013259578 | P5: 0.015629976 | Q5: 0.0087110382 | R5: 0.013582022
A6: Russell 1000 Growth | B6: 0.026336277 | C6: 0.042513645 | D6: 0.032965874 | E6: 0.039916248 | F6: 0.019266852 | G6: 0.033002399 | H6: 0.022841433 | I6: 0.03261926 | J6: 0.01901211 | K6: 0.023697441 | L6: 0.019783647 | M6: 0.025457003 | N6: 0.011050182 | O6: 0.014460598 | P6: 0.018346126 | Q6: 0.010972407 | R6: 0.01554899
A7: Russell 2000 Value | B7: 0.036700933 | C7: 0.032965874 | D7: 0.056492414 | E7: 0.053909285 | F7: 0.028796367 | G7: 0.032619399 | H7: 0.03351859 | I7: 0.038039813 | J7: 0.019842644 | K7: 0.021087 | L7: 0.020770212 | M7: 0.02285233 | N7: 0.01143833 | O7: 0.015983109 | P7: 0.01928662 | Q7: 0.010768851 | R7: 0.016874629
A8: Russell 2000 Growth | B8: 0.035440295 | C8: 0.039916248 | D8: 0.053909285 | E8: 0.05920919 | F8: 0.024807682 | G8: 0.035799572 | H8: 0.030637501 | I8: 0.039468016 | J8: 0.019539653 | K8: 0.022145286 | L8: 0.020287195 | M8: 0.024757248 | N8: 0.012379162 | O8: 0.016183475 | P8: 0.019866178 | Q8: 0.011961086 | R8: 0.016990568
A9: MSCI World Ex USA Value NR USD | B9: 0.023465053 | C9: 0.019266852 | D9: 0.028796367 | E9: 0.024807682 | F9: 0.026062263 | G9: 0.025534033 | H9: 0.027198531 | I9: 0.02807291 | J9: 0.020590381 | K9: 0.022187288 | L9: 0.018556336 | M9: 0.019821949 | N9: 0.009064868 | O9: 0.014288892 | P9: 0.015073734 | Q9: 0.0083979725 | R9: 0.013443174
A10: MSCI World Ex USA Growth NR USD | B10: 0.02711852 | C10: 0.033002399 | D10: 0.032619399 | E10: 0.035799572 | F10: 0.025534033 | G10: 0.03597751 | H10: 0.029145945 | I10: 0.03643684 | J10: 0.02298855 | K10: 0.02696198 | L10: 0.021593596 | M10: 0.025586727 | N10: 0.012440814 | O10: 0.017764882 | P10: 0.019863154 | Q10: 0.012190235 | R10: 0.016423133
A11: MSCI World Ex USA Small Value NR USD | B11: 0.025540082 | C11: 0.022841433 | D11: 0.03351859 | E11: 0.030637501 | F11: 0.027198531 | G11: 0.029145945 | H11: 0.030597549 | I11: 0.033008802 | J11: 0.02197345 | K11: 0.024429815 | L11: 0.02079704 | M11: 0.022545286 | N11: 0.01070131 | O11: 0.016154605 | P11: 0.017532959 | Q11: 0.0098097028 | R11: 0.015174961
A12: MSCI World Ex USA Small Growth NR USD | B12: 0.029016456 | C12: 0.03261926 | D12: 0.038039813 | E12: 0.039468016 | F12: 0.02807291 | G12: 0.03643684 | H12: 0.033008802 | I12: 0.039892784 | J12: 0.0243526 | K12: 0.028440812 | L12: 0.023814939 | M12: 0.02768608 | N12: 0.013125793 | O12: 0.018762225 | P12: 0.020823791 | Q12: 0.012451035 | R12: 0.017861189
A13: MSCI EM Value NR USD | B13: 0.016858308 | C13: 0.01901211 | D13: 0.019842644 | E13: 0.019539653 | F13: 0.020590381 | G13: 0.02298855 | H13: 0.02197345 | I13: 0.0243526 | J13: 0.026203563 | K13: 0.030429977 | L13: 0.020787 | M13: 0.023617448 | N13: 0.0089664254 | O13: 0.013768701 | P13: 0.013786615 | Q13: 0.0091768886 | R13: 0.011961555
A14: MSCI EM Growth NR USD | B14: 0.018704108 | C14: 0.023697441 | D14: 0.021087 | E14: 0.022145286 | F14: 0.022187288 | G14: 0.02696198 | H14: 0.024429815 | I14: 0.028440812 | J14: 0.030429977 | K14: 0.038216313 | L14: 0.023854538 | M14: 0.02830059 | N14: 0.010818312 | O14: 0.015992087 | P14: 0.016129203 | Q14: 0.011615397 | R14: 0.014221375
A15: MSCI EM Small Value NR USD | B15: 0.016871747 | C15: 0.019783647 | D15: 0.020770212 | E15: 0.020287195 | F15: 0.018556336 | G15: 0.021593596 | H15: 0.02079704 | I15: 0.023814939 | J15: 0.020787 | K15: 0.023854538 | L15: 0.020800071 | M15: 0.023024695 | N15: 0.0073752572 | O15: 0.011289889 | P15: 0.012171023 | Q15: 0.0076592666 | R15: 0.011732395
A16: MSCI EM Small Growth NR USD | B16: 0.018586928 | C16: 0.025457003 | D16: 0.02285233 | E16: 0.024757248 | F16: 0.019821949 | G16: 0.025586727 | H16: 0.022545286 | I16: 0.02768608 | J16: 0.023617448 | K16: 0.02830059 | L16: 0.023024695 | M16: 0.027523172 | N16: 0.0084932989 | O16: 0.012619599 | P16: 0.013755754 | Q16: 0.0091086859 | R16: 0.013461855
... A21: Bloomberg Barclays Global High Yield USD | B21: 0.013582022 | C21: 0.01554899 | D21: 0.016874629 | E21: 0.016990568 | F21: 0.013443174 | G21: 0.016423133 | H21: 0.015174961 | I21: 0.017861189 | J21: 0.011961555 | K21: 0.014221375 | L21: 0.011732395 | M21: 0.013461855 | N21: 0.0061066865 | O21: 0.009076174 | P21: 0.0097563161 | Q21: 0.0059351899 | R21: 0.0090869261
A23: Volatilities (annual, from final Σ)
A24: Asset | B24: Ann. Vol (sqrt of diag in decimal variance units)
A25: Russell 1000 Value | B25: 0.16891613
A26: Russell 1000 Growth | B26: 0.20618837
A27: Russell 2000 Value | B27: 0.23768133
A28: Russell 2000 Growth | B28: 0.24332939
A29: MSCI World Ex USA Value NR USD | B29: 0.16143811
A30: MSCI World Ex USA Growth NR USD | B30: 0.18967738
A31: MSCI World Ex USA Small Value NR USD | B31: 0.17492155
A32: MSCI World Ex USA Small Growth NR USD | B32: 0.19973178
A33: MSCI EM Value NR USD | B33: 0.16187515
A34: MSCI EM Growth NR USD | B34: 0.19548993
A35: MSCI EM Small Value NR USD | B35: 0.1442223
A36: MSCI EM Small Growth NR USD | B36: 0.16590109
... A41: Bloomberg Barclays Global High Yield USD | B41: 0.09532537
A43: Correlations (from final annualized Σ)
B44: Russell 1000 Value | C44: Russell 1000 Growth | D44: Russell 2000 Value | E44: Russell 2000 Growth | F44: MSCI World Ex USA Value NR USD | G44: MSCI World Ex USA Growth NR USD | H44: MSCI World Ex USA Small Value NR USD | I44: MSCI World Ex USA Small Growth NR USD | J44: MSCI EM Value NR USD | K44: MSCI EM Growth NR USD | L44: MSCI EM Small Value NR USD | M44: MSCI EM Small Growth NR USD | N44: Bloomberg Barclays US Aggregate | O44: Bloomberg Barclays Global Aggregate x USD | P44: Bloomberg Barclays Global Inflation-Linked USD | Q44: Bloomberg Barclays US Municipal Bond | R44: Bloomberg Barclays Global High Yield USD
A45: Russell 1000 Value | B45: 1 | C45: 0.75616938 | D45: 0.91413622 | E45: 0.8622469 | F45: 0.86048709 | G45: 0.84640713 | H45: 0.86438623 | I45: 0.8600547 | J45: 0.61654204 | K45: 0.5664238 | L45: 0.69255859 | M45: 0.66326527 | N45: 0.68516053 | O45: 0.71777604 | P45: 0.79325717 | Q45: 0.67338927 | R45: 0.84349943
A46: Russell 1000 Growth | B46: 0.75616938 | C46: 1 | D46: 0.67267512 | E46: 0.79559306 | F46: 0.57881601 | G46: 0.84385105 | H46: 0.63330928 | I46: 0.79206853 | J46: 0.56962098 | K46: 0.58791276 | L46: 0.66528813 | M46: 0.74420718 | N46: 0.68428423 | O46: 0.64128706 | P46: 0.76279359 | Q46: 0.69487253 | R46: 0.79109658
A47: Russell 2000 Value | B47: 0.91413622 | C47: 0.67267512 | D47: 1 | E47: 0.93212456 | F47: 0.7504756 | G47: 0.72354466 | H47: 0.80620847 | I47: 0.80130183 | J47: 0.51573225 | K47: 0.45383224 | L47: 0.60591744 | M47: 0.57954368 | N47: 0.61446736 | O47: 0.61488881 | P47: 0.69564536 | Q47: 0.59161846 | R47: 0.74478455
A48: Russell 2000 Growth | B48: 0.8622469 | C48: 0.79559306 | D48: 0.93212456 | E48: 1 | F48: 0.63151777 | G48: 0.77565345 | H48: 0.71980599 | I48: 0.81208887 | J48: 0.49606902 | K48: 0.46554572 | L48: 0.57808945 | M48: 0.61327967 | N48: 0.64957297 | O48: 0.60814564 | P48: 0.69991706 | Q48: 0.64186466 | R48: 0.7324953
A49: MSCI World Ex USA Value NR USD | B49: 0.86048709 | C49: 0.57881601 | D49: 0.7504756 | E49: 0.63151777 | F49: 1 | G49: 0.83386895 | H49: 0.96315474 | I49: 0.87063114 | J49: 0.7879128 | K49: 0.70302985 | L49: 0.79699165 | M49: 0.74010109 | N49: 0.71694638 | O49: 0.80932487 | P49: 0.80046363 | Q49: 0.67925961 | R49: 0.87354898
A50: MSCI World Ex USA Growth NR USD | B50: 0.84640713 | C50: 0.84385105 | D50: 0.72354466 | E50: 0.77565345 | F50: 0.83386895 | G50: 1 | H50: 0.87845451 | I50: 0.96178496 | J50: 0.74871383 | K50: 0.72712962 | L50: 0.78936345 | M50: 0.81311121 | N50: 0.8374608 | O50: 0.85640101 | P50: 0.89775843 | Q50: 0.83919703 | R50: 0.90830554
A51: MSCI World Ex USA Small Value NR USD | B51: 0.86438623 | C51: 0.63330928 | D51: 0.80620847 | E51: 0.71980599 | F51: 0.96315474 | G51: 0.87845451 | H51: 1 | I51: 0.94479866 | J51: 0.7760233 | K51: 0.71441812 | L51: 0.82437688 | M51: 0.77689653 | N51: 0.78113279 | O51: 0.84446842 | P51: 0.85928793 | Q51: 0.73228466 | R51: 0.91007205
...

Sheet Investment_Universe
A1: Investment universe (asset class categories)
A3: 1 | B3: Russell 1000 Value
A4: 2 | B4: Russell 1000 Growth
A5: 3 | B5: Russell 2000 Value
A6: 4 | B6: Russell 2000 Growth
A7: 5 | B7: MSCI World Ex USA Value NR USD
A8: 6 | B8: MSCI World Ex USA Growth NR USD
A9: 7 | B9: MSCI World Ex USA Small Value NR USD
A10: 8 | B10: MSCI World Ex USA Small Growth NR USD
A11: 9 | B11: MSCI EM Value NR USD
A12: 10 | B12: MSCI EM Growth NR USD
A13: 11 | B13: MSCI EM Small Value NR USD
A14: 12 | B14: MSCI EM Small Growth NR USD
... A19: 17 | B19: Bloomberg Barclays Global High Yield USD
